Workbook

Sheet LNR THÁNG  1
A1: BẢNG LỢI NHUÂN RÒNG THÁNG 1
A2: CỔ ĐÔNG | B2: VỐN CP | C2: LỢI NHUẬN GỘP | D2: LỢI NHUẬN RÒNG | E2: TỔNG NHẬN | F2: TỶ LỆ ĐT
A3: A ĐIỆP | B3: =Table73121879162330353842475259[[#This Row],[VỐN CP]]+Table951520511142528334044495457[[#This Row],[VỐN CP]] -> 69784167 | C3: =Table73121879162330353842475259[[#This Row],[LỢI NHUẬN GỘP]]+Table951520511142528334044495457[[#This Row],[LỢI NHUẬN GỘP]] -> 21976044 | D3: =Table73121879162330353842475259[[#This Row],[LỢI NHUẬN RÒNG]]+Table951520511142528334044495457[[#This Row],[LỢI NHUẬN RÒNG]] -> 12987740 | E3: =Table73121879162330353842475259[[#This Row],[TỔNG NHẬN]]+Table951520511142528334044495457[[#This Row],[TỔNG NHẬN]] -> 82771906 | F3: =D3/B3 -> 0.18611299
A4: CHIẾN | B4: =Table73121879162330353842475259[[#This Row],[VỐN CP]] -> 81893333 | C4: =Table73121879162330353842475259[[#This Row],[LỢI NHUẬN GỘP]] -> 24281548 | D4: =Table73121879162330353842475259[[#This Row],[LỢI NHUẬN RÒNG]] -> 14639970 | E4: =Table73121879162330353842475259[[#This Row],[TỔNG NHẬN]] -> 96533303 | F4: =D4/B4 -> 0.17876877
A5: CHUNG | B5: =Table73121879162330353842475259[[#This Row],[VỐN CP]]+'Tháng 1 nhà S'!L4 -> 7.8874083e+08 | C5: =Table73121879162330353842475259[[#This Row],[LỢI NHUẬN GỘP]]+'Tháng 1 nhà S'!M4 -> 2.7106696e+08 | D5: =Table73121879162330353842475259[[#This Row],[LỢI NHUẬN RÒNG]]+'Tháng 1 nhà S'!N4 -> 1.6973725e+08 | E5: =Table73121879162330353842475259[[#This Row],[TỔNG NHẬN]]+'Tháng 1 nhà S'!O4 -> 9.5847808e+08 | F5: =D5/B5 -> 0.21520028
A6: Đ. THẮNG | B6: =Table73121879162330353842475259[[#This Row],[VỐN CP]]+'Tháng 1 nhà S'!L5 -> 75105000 | C6: =Table73121879162330353842475259[[#This Row],[LỢI NHUẬN GỘP]]+'Tháng 1 nhà S'!M5 -> 23106801 | D6: =Table73121879162330353842475259[[#This Row],[LỢI NHUẬN RÒNG]]+'Tháng 1 nhà S'!N5 -> 13600861 | E6: =Table73121879162330353842475259[[#This Row],[TỔNG NHẬN]]+'Tháng 1 nhà S'!O5 -> 88705861 | F6: =D6/B6 -> 0.18109129
A7: ĐẠT | B7: =Table73121879162330353842475259[[#This Row],[VỐN CP]]+'Tháng 1 nhà S'!L6 -> 35213333 | C7: =Table73121879162330353842475259[[#This Row],[LỢI NHUẬN GỘP]]+'Tháng 1 nhà S'!M6 -> 12971636 | D7: =Table73121879162330353842475259[[#This Row],[LỢI NHUẬN RÒNG]]+'Tháng 1 nhà S'!N6 -> 8543096 | E7: =Table73121879162330353842475259[[#This Row],[TỔNG NHẬN]]+'Tháng 1 nhà S'!O6 -> 43756429 | F7: =D7/B7 -> 0.24260969
A8: DT | B8: ='Tháng 1 nhà S'!L7 -> 6795000 | C8: ='Tháng 1 nhà S'!M7 -> 3124019.9 | D8: ='Tháng 1 nhà S'!N7 -> 2375974.3 | E8: ='Tháng 1 nhà S'!O7 -> 9170974.3 | F8: =D8/B8 -> 0.3496651
A9: HẰNG | B9: ='Tháng 1 nhà T '!L8+'Tháng 1 nhà S'!L8 -> 8.0778333e+08 | C9: ='Tháng 1 nhà T '!M8+'Tháng 1 nhà S'!M8 -> 2.6698156e+08 | D9: ='Tháng 1 nhà T '!N8+'Tháng 1 nhà S'!N8 -> 1.6079777e+08 | E9: ='Tháng 1 nhà T '!O8+'Tháng 1 nhà S'!O8 -> 9.3513017e+08 | F9: =D9/B9 -> 0.19906052
A10: HÀO | B10: ='Tháng 1 nhà T '!L9+'Tháng 1 nhà S'!L9 -> 4.1494333e+08 | C10: ='Tháng 1 nhà T '!M9+'Tháng 1 nhà S'!M9 -> 1.5002235e+08 | D10: ='Tháng 1 nhà T '!N9+'Tháng 1 nhà S'!N9 -> 1.0003717e+08 | E10: ='Tháng 1 nhà T '!O9+'Tháng 1 nhà S'!O9 -> 5.1498051e+08 | F10: =D10/B10 -> 0.24108635
A11: HUY | B11: ='Tháng 1 nhà T '!L10+'Tháng 1 nhà S'!L10 -> 51435000 | C11: ='Tháng 1 nhà T '!M10+'Tháng 1 nhà S'!M10 -> 15085243 | D11: ='Tháng 1 nhà T '!N10+'Tháng 1 nhà S'!N10 -> 7627804.1 | E11: ='Tháng 1 nhà T '!O10+'Tháng 1 nhà S'!O10 -> 59062804 | F11: =D11/B11 -> 0.14829987
A12: HUY ANH | B12: ='Tháng 1 nhà T '!L16+'Tháng 1 nhà S'!L11 -> 99101667 | C12: ='Tháng 1 nhà T '!M16+'Tháng 1 nhà S'!M11 -> 35197056 | D12: ='Tháng 1 nhà T '!N16+'Tháng 1 nhà S'!N11 -> 24431148 | E12: ='Tháng 1 nhà T '!O16+'Tháng 1 nhà S'!O11 -> 1.2353282e+08 | F12: =D12/B12 -> 0.24652611
A13: KIÊN | B13: ='Tháng 1 nhà T '!L11+'Tháng 1 nhà S'!L12 -> 4.0571833e+08 | C13: ='Tháng 1 nhà T '!M11+'Tháng 1 nhà S'!M12 -> 1.4162093e+08 | D13: ='Tháng 1 nhà T '!N11+'Tháng 1 nhà S'!N12 -> 81365506 | E13: ='Tháng 1 nhà T '!O11+'Tháng 1 nhà S'!O12 -> 4.8708384e+08 | F13: =D13/B13 -> 0.20054678
A14: LUẬN | B14: ='Tháng 1 nhà S'!L13 -> 38973333 | C14: ='Tháng 1 nhà S'!M13 -> 16571624 | D14: ='Tháng 1 nhà S'!N13 -> 11190578 | E14: ='Tháng 1 nhà S'!O13 -> 50163911 | F14: =D14/B14 -> 0.28713422
A15: MẠNH | B15: ='Tháng 1 nhà T '!L12+'Tháng 1 nhà S'!L14 -> 191020000 | C15: ='Tháng 1 nhà T '!M12+'Tháng 1 nhà S'!M14 -> 64356110 | D15: ='Tháng 1 nhà T '!N12+'Tháng 1 nhà S'!N14 -> 40229351 | E15: ='Tháng 1 nhà T '!O12+'Tháng 1 nhà S'!O14 -> 2.3124935e+08 | F15: =D15/B15 -> 0.21060282
A16: N. THẮNG | B16: ='Tháng 1 nhà T '!L13 -> 8400000 | C16: ='Tháng 1 nhà T '!M13 -> 5211706 | D16: ='Tháng 1 nhà T '!N13 -> 2937946.8 | E16: ='Tháng 1 nhà T '!O13 -> 11337947 | F16: =D16/B16 -> 0.34975558
A17: NGỌC | B17: ='Tháng 1 nhà T '!L14+'Tháng 1 nhà S'!L15 -> 79818333 | C17: ='Tháng 1 nhà T '!M14+'Tháng 1 nhà S'!M15 -> 28010797 | D17: ='Tháng 1 nhà T '!N14+'Tháng 1 nhà S'!N15 -> 18063571 | E17: ='Tháng 1 nhà T '!O14+'Tháng 1 nhà S'!O15 -> 97881904 | F17: =D17/B17 -> 0.22630854
A18: NỤ | B18: ='Tháng 1 nhà S'!L16 -> 52721667 | C18: ='Tháng 1 nhà S'!M16 -> 19022348 | D18: ='Tháng 1 nhà S'!N16 -> 12775747 | E18: ='Tháng 1 nhà S'!O16 -> 65497414 | F18: =D18/B18 -> 0.24232442
A19: TÙNG | B19: ='Tháng 1 nhà T '!L15+'Tháng 1 nhà S'!L17 -> 2.0561833e+08 | C19: ='Tháng 1 nhà T '!M15+'Tháng 1 nhà S'!M17 -> 74470186 | D19: ='Tháng 1 nhà T '!N15+'Tháng 1 nhà S'!N17 -> 49471606 | E19: ='Tháng 1 nhà T '!O15+'Tháng 1 nhà S'!O17 -> 2.5508994e+08 | F19: =D19/B19 -> 0.2405992
A20: CƯỜNG | B20: ='Tháng 1 nhà S'!L18 -> 1583333.3 | C20: ='Tháng 1 nhà S'!M18 -> 890396.97 | D20: ='Tháng 1 nhà S'!N18 -> 733654.19 | E20: ='Tháng 1 nhà S'!O18 -> 2316987.5 | F20: =D20/B20 -> 0.46336054
A21: HƯƠNG ANH | B21: ='Tháng 1 nhà S'!L19 -> 2533333.3 | C21: ='Tháng 1 nhà S'!M19 -> 1317041.2 | D21: ='Tháng 1 nhà S'!N19 -> 1025904.7 | E21: ='Tháng 1 nhà S'!O19 -> 3559238.1 | F21: =D21/B21 -> 0.40496239
A22: HOÀNG ANH | B22: ='Tháng 1 nhà S'!L20 -> 2083333.3 | C22: ='Tháng 1 nhà S'!M20 -> 1330249.2 | D22: ='Tháng 1 nhà S'!N20 -> 932414.38 | E22: ='Tháng 1 nhà S'!O20 -> 3015747.7 | F22: =D22/B22 -> 0.4475589
A23: LÂM | B23: ='Tháng 1 nhà S'!L21 -> 89468333 | C23: ='Tháng 1 nhà S'!M21 -> 31659904 | D23: ='Tháng 1 nhà S'!N21 -> 22401581 | E23: ='Tháng 1 nhà S'!O21 -> 1.1186991e+08 | F23: =D23/B23 -> 0.25038559
A24: LINH | B24: ='Tháng 1 nhà S'!L22 -> 4700000 | C24: ='Tháng 1 nhà S'!M22 -> 2696858.6 | D24: ='Tháng 1 nhà S'!N22 -> 1723105.4 | E24: ='Tháng 1 nhà S'!O22 -> 6423105.4 | F24: =D24/B24 -> 0.36661817
A25: HUYỀN | B25: ='Tháng 1 nhà S'!L23 -> 13700000 | C25: ='Tháng 1 nhà S'!M23 -> 4908757.6 | D25: ='Tháng 1 nhà S'!N23 -> 3503690.2 | E25: ='Tháng 1 nhà S'!O23 -> 17203690 | F25: =D25/B25 -> 0.25574381
A26: ƯỚC | B26: ='Tháng 1 nhà S'!L24 -> 13350000 | C26: ='Tháng 1 nhà S'!M24 -> 4392079 | D26: ='Tháng 1 nhà S'!N24 -> 2997536.4 | E26: ='Tháng 1 nhà S'!O24 -> 16347536 | F26: =D26/B26 -> 0.22453456
A27: TỎNG | B27: ='[1]Tháng 9 nhà S '!L25 -> 1.7451667e+09 | C27: =SUBTOTAL(109,C2:C26) -> 1.2202722e+09 | D27: =SUBTOTAL(109,D2:D26) -> 7.6413097e+08 | E27: =SUBTOTAL(109,E2:E26) -> 4.2711634e+09 | F27: =D27/B27 -> 0.43785558

Sheet Tháng 1 nhà T  
A1: BẢNG CHIA CỔ PHẦN THÁNG 1.26 NHÀ T
K2: CỔ ĐÔNG | L2: VỐN CP | M2: LỢI NHUẬN GỘP | N2: LỢI NHUẬN RÒNG | O2: TỔNG NHẬN
A3: MÃ TOÀ | B3: CỔ ĐÔNG | C3: TỈ LỆ % | D3: VỐN CP | E3: LỢI NHUẬN GỘP | F3: LỢI NHUẬN RÒNG | G3: TỔNG NHẬN | K3: A ĐIỆP | L3: =SUMIF($B$4:$B$155,K3,$D$4:$D$155) -> 21095833 | M3: =SUMIF('Tháng 1 nhà T '!$B$4:$B$154,K3,'Tháng 1 nhà T '!$E$4:$E$154) -> 3878979 | N3: =SUMIF('Tháng 1 nhà T '!$B$4:$B$154,K3,'Tháng 1 nhà T '!$F$4:$F$154) -> 1471327.7 | O3: =SUMIF('Tháng 1 nhà T '!$B$4:$B$154,K3,'Tháng 1 nhà T '!$G$4:$G$154) -> 22567161
A4: T33 | B4: CHUNG | C4: 30 | D4: 13200000 | E4: 4928485.5 | F4: 3069862.5 | G4: =Table52111768152229343741465158[[#This Row],[LỢI NHUẬN RÒNG]]+Table52111768152229343741465158[[#This Row],[VỐN CP]] -> 16269863 | K4: CHIẾN | L4: =SUMIF($B$4:$B$155,K4,$D$4:$D$155) -> 81893333 | M4: =SUMIF('Tháng 1 nhà T '!$B$4:$B$154,K4,'Tháng 1 nhà T '!$E$4:$E$154) -> 24281548 | N4: =SUMIF('Tháng 1 nhà T '!$B$4:$B$154,K4,'Tháng 1 nhà T '!$F$4:$F$154) -> 14639970 | O4: =SUMIF('Tháng 1 nhà T '!$B$4:$B$154,K4,'Tháng 1 nhà T '!$G$4:$G$154) -> 96533303
A5: T33 | B5: HẰNG | C5: 30 | D5: 13200000 | E5: 4928485.5 | F5: 3069862.5 | G5: =Table52111768152229343741465158[[#This Row],[LỢI NHUẬN RÒNG]]+Table52111768152229343741465158[[#This Row],[VỐN CP]] -> 16269863 | K5: CHUNG | L5: =SUMIF($B$4:$B$155,K5,$D$4:$D$155) -> 4.1166417e+08 | M5: =SUMIF('Tháng 1 nhà T '!$B$4:$B$154,K5,'Tháng 1 nhà T '!$E$4:$E$154) -> 1.3808988e+08 | N5: =SUMIF('Tháng 1 nhà T '!$B$4:$B$154,K5,'Tháng 1 nhà T '!$F$4:$F$154) -> 79345994 | O5: =SUMIF('Tháng 1 nhà T '!$B$4:$B$154,K5,'Tháng 1 nhà T '!$G$4:$G$154) -> 4.9101016e+08
A6: T33 | B6: HÀO | C6: 10 | D6: 4400000 | E6: 1642828.5 | F6: 1023287.5 | G6: =Table52111768152229343741465158[[#This Row],[LỢI NHUẬN RÒNG]]+Table52111768152229343741465158[[#This Row],[VỐN CP]] -> 5423287.5 | K6: Đ. THẮNG | L6: =SUMIF($B$4:$B$155,K6,$D$4:$D$155) -> 10693333 | M6: =SUMIF('Tháng 1 nhà T '!$B$4:$B$154,K6,'Tháng 1 nhà T '!$E$4:$E$154) -> 636610.57 | N6: =SUMIF('Tháng 1 nhà T '!$B$4:$B$154,K6,'Tháng 1 nhà T '!$F$4:$F$154) -> -354918.25 | O6: =SUMIF('Tháng 1 nhà T '!$B$4:$B$154,K6,'Tháng 1 nhà T '!$G$4:$G$154) -> 10338415
A7: T33 | B7: KIÊN | C7: 20 | D7: 8800000 | E7: 3285657 | F7: 2046575 | G7: =Table52111768152229343741465158[[#This Row],[LỢI NHUẬN RÒNG]]+Table52111768152229343741465158[[#This Row],[VỐN CP]] -> 10846575 | K7: ĐẠT | L7: =SUMIF($B$4:$B$155,K7,$D$4:$D$155) -> 6666666.7 | M7: =SUMIF('Tháng 1 nhà T '!$B$4:$B$154,K7,'Tháng 1 nhà T '!$E$4:$E$154) -> 822070.73 | N7: =SUMIF('Tháng 1 nhà T '!$B$4:$B$154,K7,'Tháng 1 nhà T '!$F$4:$F$154) -> 179299.52 | O7: =SUMIF('Tháng 1 nhà T '!$B$4:$B$154,K7,'Tháng 1 nhà T '!$G$4:$G$154) -> 6845966.2
A8: T33 | B8: MẠNH | C8: 10 | D8: 4400000 | E8: 1642828.5 | F8: 1023287.5 | G8: =Table52111768152229343741465158[[#This Row],[LỢI NHUẬN RÒNG]]+Table52111768152229343741465158[[#This Row],[VỐN CP]] -> 5423287.5 | K8: HẰNG | L8: =SUMIF($B$4:$B$155,K8,$D$4:$D$155) -> 413860000 | M8: =SUMIF('Tháng 1 nhà T '!$B$4:$B$154,K8,'Tháng 1 nhà T '!$E$4:$E$154) -> 1.3796272e+08 | N8: =SUMIF('Tháng 1 nhà T '!$B$4:$B$154,K8,'Tháng 1 nhà T '!$F$4:$F$154) -> 79513416 | O8: =SUMIF('Tháng 1 nhà T '!$B$4:$B$154,K8,'Tháng 1 nhà T '!$G$4:$G$154) -> 4.5992249e+08
A9: T37 | B9: CHUNG | C9: 15 | D9: 10000000 | E9: 1233106.1 | F9: 268949.28 | G9: =Table52111768152229343741465158[[#This Row],[LỢI NHUẬN RÒNG]]+Table52111768152229343741465158[[#This Row],[VỐN CP]] -> 10268949 | K9: HÀO | L9: =SUMIF($B$4:$B$155,K9,$D$4:$D$155) -> 68785000 | M9: =SUMIF('Tháng 1 nhà T '!$B$4:$B$154,K9,'Tháng 1 nhà T '!$E$4:$E$154) -> 26646326 | N9: =SUMIF('Tháng 1 nhà T '!$B$4:$B$154,K9,'Tháng 1 nhà T '!$F$4:$F$154) -> 17441227 | O9: =SUMIF('Tháng 1 nhà T '!$B$4:$B$154,K9,'Tháng 1 nhà T '!$G$4:$G$154) -> 86226227
A10: T37 | B10: ĐẠT | C10: 10 | D10: 6666666.7 | E10: 822070.73 | F10: 179299.52 | G10: =Table52111768152229343741465158[[#This Row],[LỢI NHUẬN RÒNG]]+Table52111768152229343741465158[[#This Row],[VỐN CP]] -> 6845966.2 | K10: HUY | L10: =SUMIF($B$4:$B$155,K10,$D$4:$D$155) -> 16000000 | M10: =SUMIF('Tháng 1 nhà T '!$B$4:$B$154,K10,'Tháng 1 nhà T '!$E$4:$E$154) -> 4816046.6 | N10: =SUMIF('Tháng 1 nhà T '!$B$4:$B$154,K10,'Tháng 1 nhà T '!$F$4:$F$154) -> 1578919 | O10: =SUMIF('Tháng 1 nhà T '!$B$4:$B$154,K10,'Tháng 1 nhà T '!$G$4:$G$154) -> 17578919
A11: T37 | B11: HẰNG | C11: 15 | D11: 10000000 | E11: 1233106.1 | F11: 268949.28 | G11: =Table52111768152229343741465158[[#This Row],[LỢI NHUẬN RÒNG]]+Table52111768152229343741465158[[#This Row],[VỐN CP]] -> 10268949 | K11: KIÊN | L11: =SUMIF($B$4:$B$155,K11,$D$4:$D$155) -> 3.2734833e+08 | M11: =SUMIF('Tháng 1 nhà T '!$B$4:$B$154,K11,'Tháng 1 nhà T '!$E$4:$E$154) -> 1.1833975e+08 | N11: =SUMIF('Tháng 1 nhà T '!$B$4:$B$154,K11,'Tháng 1 nhà T '!$F$4:$F$154) -> 66617994 | O11: =SUMIF(Table52111768152229343741465158[CỔ ĐÔNG],K11,Table52111768152229343741465158[TỔNG NHẬN]) -> 3.9396633e+08
A12: T37 | B12: HÀO | C12: 10 | D12: 6666666.7 | E12: 822070.73 | F12: 179299.52 | G12: =Table52111768152229343741465158[[#This Row],[LỢI NHUẬN RÒNG]]+Table52111768152229343741465158[[#This Row],[VỐN CP]] -> 6845966.2 | K12: MẠNH | L12: =SUMIF($B$4:$B$155,K12,$D$4:$D$155) -> 44946667 | M12: =SUMIF('Tháng 1 nhà T '!$B$4:$B$154,K12,'Tháng 1 nhà T '!$E$4:$E$154) -> 12009010 | N12: =SUMIF('Tháng 1 nhà T '!$B$4:$B$154,K12,'Tháng 1 nhà T '!$F$4:$F$154) -> 6367755.8 | O12: =SUMIF('Tháng 1 nhà T '!$B$4:$B$154,K12,'Tháng 1 nhà T '!$G$4:$G$154) -> 51314422
A13: T37 | B13: KIÊN | C13: 10 | D13: 6666666.7 | E13: 822070.73 | F13: 179299.52 | G13: =Table52111768152229343741465158[[#This Row],[LỢI NHUẬN RÒNG]]+Table52111768152229343741465158[[#This Row],[VỐN CP]] -> 6845966.2 | K13: N. THẮNG | L13: =SUMIF($B$4:$B$155,K13,$D$4:$D$155) -> 8400000 | M13: =SUMIF('Tháng 1 nhà T '!$B$4:$B$154,K13,'Tháng 1 nhà T '!$E$4:$E$154) -> 5211706 | N13: =SUMIF('Tháng 1 nhà T '!$B$4:$B$154,K13,'Tháng 1 nhà T '!$F$4:$F$154) -> 2937946.8 | O13: =SUMIF('Tháng 1 nhà T '!$B$4:$B$154,K13,'Tháng 1 nhà T '!$G$4:$G$154) -> 11337947
A14: T37 | B14: MẠNH | C14: 10 | D14: 6666666.7 | E14: 822070.73 | F14: 179299.52 | G14: =Table52111768152229343741465158[[#This Row],[LỢI NHUẬN RÒNG]]+Table52111768152229343741465158[[#This Row],[VỐN CP]] -> 6845966.2 | K14: NGỌC | L14: =SUMIF($B$4:$B$155,K14,$D$4:$D$155) -> 17560000 | M14: =SUMIF('Tháng 1 nhà T '!$B$4:$B$154,K14,'Tháng 1 nhà T '!$E$4:$E$154) -> 4665013.1 | N14: =SUMIF('Tháng 1 nhà T '!$B$4:$B$154,K14,'Tháng 1 nhà T '!$F$4:$F$154) -> 2038947.8 | O14: =SUMIF('Tháng 1 nhà T '!$B$4:$B$154,K14,'Tháng 1 nhà T '!$G$4:$G$154) -> 19598948
A15: T37 | B15: TÙNG | C15: 20 | D15: 13333333 | E15: 1644141.5 | F15: 358599.05 | G15: =Table52111768152229343741465158[[#This Row],[LỢI NHUẬN RÒNG]]+Table52111768152229343741465158[[#This Row],[VỐN CP]] -> 13691932 | K15: TÙNG | L15: =SUMIF($B$4:$B$155,K15,$D$4:$D$155) -> 42353333 | M15: =SUMIF('Tháng 1 nhà T '!$B$4:$B$154,K15,'Tháng 1 nhà T '!$E$4:$E$154) -> 11045510 | N15: =SUMIF('Tháng 1 nhà T '!$B$4:$B$154,K15,'Tháng 1 nhà T '!$F$4:$F$154) -> 5472285.9 | O15: =SUMIF('Tháng 1 nhà T '!$B$4:$B$154,K15,'Tháng 1 nhà T '!$G$4:$G$154) -> 47825619
A16: T38 | B16: CHUNG | C16: 30 | D16: 7950000 | E16: 2634169.8 | F16: 1783847.1 | G16: =Table52111768152229343741465158[[#This Row],[LỢI NHUẬN RÒNG]]+Table52111768152229343741465158[[#This Row],[VỐN CP]] -> 9733847.1 | K16: HUY ANH | L16: =SUMIF($B$4:$B$155,K16,$D$4:$D$155) -> 2750000 | M16: =SUMIF('Tháng 1 nhà T '!$B$4:$B$154,K16,'Tháng 1 nhà T '!$E$4:$E$154) -> 423000 | N16: =SUMIF('Tháng 1 nhà T '!$B$4:$B$154,K16,'Tháng 1 nhà T '!$F$4:$F$154) -> 18494.871 | O16: =SUMIF('Tháng 1 nhà T '!$B$4:$B$154,K16,'Tháng 1 nhà T '!$G$4:$G$154) -> 2768494.9
A17: T38 | B17: HẰNG | C17: 30 | D17: 7950000 | E17: 2634169.8 | F17: 1783847.1 | G17: =Table52111768152229343741465158[[#This Row],[LỢI NHUẬN RÒNG]]+Table52111768152229343741465158[[#This Row],[VỐN CP]] -> 9733847.1 | K17: TỔNG | L17: =SUM(L2:L16) -> 1.4740167e+09 | M17: =SUM(M2:M16) -> 488828169 | N17: =SUM(N2:N16) -> 2.7726866e+08 | O17: =SUM(O2:O16) -> 1.7178344e+09
A18: T38 | B18: HÀO | C18: 10 | D18: 2650000 | E18: 878056.6 | F18: 594615.7 | G18: =Table52111768152229343741465158[[#This Row],[LỢI NHUẬN RÒNG]]+Table52111768152229343741465158[[#This Row],[VỐN CP]] -> 3244615.7
A19: T38 | B19: KIÊN | C19: 20 | D19: 5300000 | E19: 1756113.2 | F19: 1189231.4 | G19: =Table52111768152229343741465158[[#This Row],[LỢI NHUẬN RÒNG]]+Table52111768152229343741465158[[#This Row],[VỐN CP]] -> 6489231.4
A20: T38 | B20: NGỌC | C20: 10 | D20: 2650000 | E20: 878056.6 | F20: 594615.7 | G20: =Table52111768152229343741465158[[#This Row],[LỢI NHUẬN RÒNG]]+Table52111768152229343741465158[[#This Row],[VỐN CP]] -> 3244615.7
A21: T41 | B21: CHUNG | C21: 25 | D21: 13750000 | E21: 2115000 | F21: 92474.355 | G21: =Table52111768152229343741465158[[#This Row],[LỢI NHUẬN RÒNG]]+Table52111768152229343741465158[[#This Row],[VỐN CP]] -> 13842474
A22: T41 | B22: HẰNG | C22: 25 | D22: 13750000 | E22: 2115000 | F22: 92474.355 | G22: =Table52111768152229343741465158[[#This Row],[LỢI NHUẬN RÒNG]]+Table52111768152229343741465158[[#This Row],[VỐN CP]] -> 13842474
A23: T41 | B23: HUY ANH | C23: 5 | D23: 2750000 | E23: 423000 | F23: 18494.871 | G23: =Table52111768152229343741465158[[#This Row],[LỢI NHUẬN RÒNG]]+Table52111768152229343741465158[[#This Row],[VỐN CP]] -> 2768494.9
A24: T41 | B24: NGỌC | C24: 5 | D24: 2750000 | E24: 423000 | F24: 18494.871 | G24: =Table52111768152229343741465158[[#This Row],[LỢI NHUẬN RÒNG]]+Table52111768152229343741465158[[#This Row],[VỐN CP]] -> 2768494.9
A25: T41 | B25: KIÊN | C25: 20 | D25: 11000000 | E25: 1692000 | F25: 73979.484 | G25: =Table52111768152229343741465158[[#This Row],[LỢI NHUẬN RÒNG]]+Table52111768152229343741465158[[#This Row],[VỐN CP]] -> 11073979
A26: T41 | B26: MẠNH | C26: 10 | D26: 5500000 | E26: 846000 | F26: 36989.742 | G26: =Table52111768152229343741465158[[#This Row],[LỢI NHUẬN RÒNG]]+Table52111768152229343741465158[[#This Row],[VỐN CP]] -> 5536989.7
A27: T42 | B27: CHUNG | C27: 35 | D27: 45237500 | E27: 15298730 | F27: 10221248 | G27: =Table52111768152229343741465158[[#This Row],[LỢI NHUẬN RÒNG]]+Table52111768152229343741465158[[#This Row],[VỐN CP]] -> 55458748
A28: T42 | B28: HẰNG | C28: 40 | D28: 51700000 | E28: 17484263 | F28: 11681427 | G28: =Table52111768152229343741465158[[#This Row],[LỢI NHUẬN RÒNG]]+Table52111768152229343741465158[[#This Row],[VỐN CP]] -> 63381427
A29: T42 | B29: HÀO | C29: 10 | D29: 12925000 | E29: 4371065.8 | F29: 2920356.7 | G29: =Table52111768152229343741465158[[#This Row],[LỢI NHUẬN RÒNG]]+Table52111768152229343741465158[[#This Row],[VỐN CP]] -> 15845357
... A88: T25 | B88: CHUNG | C88: 30 | D88: 33000000 | E88: 13952241 | F88: 7141115.4 | G88: =Table52111768152229343741465158[[#This Row],[LỢI NHUẬN RÒNG]]+Table52111768152229343741465158[[#This Row],[VỐN CP]] -> 40141115
A89: T25 | B89: HẰNG | C89: 25 | D89: 27500000 | E89: 11626867 | F89: 5950929.5
A90: T25 | B90: HÀO | C90: 15 | D90: 16500000 | E90: 6976120.3 | F90: 3570557.7 | G90: =Table52111768152229343741465158[[#This Row],[LỢI NHUẬN RÒNG]]+Table52111768152229343741465158[[#This Row],[VỐN CP]] -> 20070558
A91: T25 | B91: KIÊN | C91: 20 | D91: 22000000 | E91: 9301493.8 | F91: 4760743.6 | G91: =Table52111768152229343741465158[[#This Row],[LỢI NHUẬN RÒNG]]+Table52111768152229343741465158[[#This Row],[VỐN CP]] -> 26760744
A92: T25 | B92: TÙNG | C92: 10 | D92: 11000000 | E92: 4650746.9 | F92: 2380371.8 | G92: =Table52111768152229343741465158[[#This Row],[LỢI NHUẬN RÒNG]]+Table52111768152229343741465158[[#This Row],[VỐN CP]] -> 13380372
A93: T26 | B93: CHUNG | C93: 25 | D93: 12500000 | E93: 3443460.5 | F93: 2100771.4 | G93: =Table52111768152229343741465158[[#This Row],[LỢI NHUẬN RÒNG]]+Table52111768152229343741465158[[#This Row],[VỐN CP]] -> 14600771
A94: T26 | B94: HẰNG | C94: 25 | D94: 12500000 | E94: 3443460.5 | F94: 2100771.4 | G94: =Table52111768152229343741465158[[#This Row],[LỢI NHUẬN RÒNG]]+Table52111768152229343741465158[[#This Row],[VỐN CP]] -> 14600771
A95: T26 | B95: HUY | C95: 10 | D95: 5000000 | E95: 1377384.2 | F95: 840308.54 | G95: =Table52111768152229343741465158[[#This Row],[LỢI NHUẬN RÒNG]]+Table52111768152229343741465158[[#This Row],[VỐN CP]] -> 5840308.5
A96: T26 | B96: KIÊN | C96: 40 | D96: 20000000 | E96: 5509536.8 | F96: 3361234.2 | G96: =Table52111768152229343741465158[[#This Row],[LỢI NHUẬN RÒNG]]+Table52111768152229343741465158[[#This Row],[VỐN CP]] -> 23361234
A97: T27 | B97: CHUNG | C97: 25 | D97: 14400000 | E97: 1464649.8 | F97: 138404.18 | G97: =Table52111768152229343741465158[[#This Row],[LỢI NHUẬN RÒNG]]+Table52111768152229343741465158[[#This Row],[VỐN CP]] -> 14538404
A98: T27 | B98: Đ. THẮNG | C98: 10 | D98: 5760000 | E98: 585859.9 | F98: 55361.673 | G98: =Table52111768152229343741465158[[#This Row],[LỢI NHUẬN RÒNG]]+Table52111768152229343741465158[[#This Row],[VỐN CP]] -> 5815361.7
...

Sheet Tháng 3 nhà T  
A1: BẢNG CHIA CỔ PHẦN THÁNG 3.26 NHÀ T
K2: CỔ ĐÔNG | L2: VỐN CP | M2: LỢI NHUẬN GỘP | N2: LỢI NHUẬN RÒNG | O2: TỔNG NHẬN
A3: MÃ TOÀ | B3: CỔ ĐÔNG | C3: TỈ LỆ % | D3: VỐN CP | E3: LỢI NHUẬN GỘP | F3: LỢI NHUẬN RÒNG | G3: TỔNG NHẬN | K3: A ĐIỆP | L3: =SUMIF($B$4:$B$155,K3,$D$4:$D$155) -> 21095833 | M3: =SUMIF('Tháng 3 nhà T '!$B$4:$B$154,K3,'Tháng 3 nhà T '!$E$4:$E$154) -> 2901245.6 | N3: =SUMIF('Tháng 3 nhà T '!$B$4:$B$154,K3,'Tháng 3 nhà T '!$F$4:$F$154) -> 169181.99 | O3: =SUMIF('Tháng 3 nhà T '!$B$4:$B$154,K3,'Tháng 3 nhà T '!$G$4:$G$154) -> 21265015
A4: T33 | B4: CHUNG | C4: 30 | D4: 13200000 | E4: 5360637 | F4: 4219731.7 | G4: =Table52111768152229343741465158916[[#This Row],[LỢI NHUẬN RÒNG]]+Table52111768152229343741465158916[[#This Row],[VỐN CP]] -> 17419732 | K4: CHIẾN | L4: =SUMIF($B$4:$B$155,K4,$D$4:$D$155) -> 81893333 | M4: =SUMIF('Tháng 3 nhà T '!$B$4:$B$154,K4,'Tháng 3 nhà T '!$E$4:$E$154) -> 27512028 | N4: =SUMIF('Tháng 3 nhà T '!$B$4:$B$154,K4,'Tháng 3 nhà T '!$F$4:$F$154) -> 17408162 | O4: =SUMIF('Tháng 3 nhà T '!$B$4:$B$154,K4,'Tháng 3 nhà T '!$G$4:$G$154) -> 99301495
A5: T33 | B5: HẰNG | C5: 30 | D5: 13200000 | E5: 5360637 | F5: 4219731.7 | G5: =Table52111768152229343741465158916[[#This Row],[LỢI NHUẬN RÒNG]]+Table52111768152229343741465158916[[#This Row],[VỐN CP]] -> 17419732 | K5: CHUNG | L5: =SUMIF($B$4:$B$155,K5,$D$4:$D$155) -> 4.1166417e+08 | M5: =SUMIF('Tháng 3 nhà T '!$B$4:$B$154,K5,'Tháng 3 nhà T '!$E$4:$E$154) -> 1.2793461e+08 | N5: =SUMIF('Tháng 3 nhà T '!$B$4:$B$154,K5,'Tháng 3 nhà T '!$F$4:$F$154) -> 74392778 | O5: =SUMIF('Tháng 3 nhà T '!$B$4:$B$154,K5,'Tháng 3 nhà T '!$G$4:$G$154) -> 4.8605694e+08
A6: T33 | B6: HÀO | C6: 10 | D6: 4400000 | E6: 1786879 | F6: 1406577.2 | G6: =Table52111768152229343741465158916[[#This Row],[LỢI NHUẬN RÒNG]]+Table52111768152229343741465158916[[#This Row],[VỐN CP]] -> 5806577.2 | K6: Đ. THẮNG | L6: =SUMIF($B$4:$B$155,K6,$D$4:$D$155) -> 10693333 | M6: =SUMIF('Tháng 3 nhà T '!$B$4:$B$154,K6,'Tháng 3 nhà T '!$E$4:$E$154) -> -1077774.6 | N6: =SUMIF('Tháng 3 nhà T '!$B$4:$B$154,K6,'Tháng 3 nhà T '!$F$4:$F$154) -> -1971771.2 | O6: =SUMIF('Tháng 3 nhà T '!$B$4:$B$154,K6,'Tháng 3 nhà T '!$G$4:$G$154) -> 8721562.1
A7: T33 | B7: KIÊN | C7: 20 | D7: 8800000 | E7: 3573758 | F7: 2813154.5 | G7: =Table52111768152229343741465158916[[#This Row],[LỢI NHUẬN RÒNG]]+Table52111768152229343741465158916[[#This Row],[VỐN CP]] -> 11613154 | K7: ĐẠT | L7: =SUMIF($B$4:$B$155,K7,$D$4:$D$155) -> 6666666.7 | M7: =SUMIF('Tháng 3 nhà T '!$B$4:$B$154,K7,'Tháng 3 nhà T '!$E$4:$E$154) -> 10073.933 | N7: =SUMIF('Tháng 3 nhà T '!$B$4:$B$154,K7,'Tháng 3 nhà T '!$F$4:$F$154) -> -641895.79 | O7: =SUMIF('Tháng 3 nhà T '!$B$4:$B$154,K7,'Tháng 3 nhà T '!$G$4:$G$154) -> 6024770.9
A8: T33 | B8: MẠNH | C8: 10 | D8: 4400000 | E8: 1786879 | F8: 1406577.2 | G8: =Table52111768152229343741465158916[[#This Row],[LỢI NHUẬN RÒNG]]+Table52111768152229343741465158916[[#This Row],[VỐN CP]] -> 5806577.2 | K8: HẰNG | L8: =SUMIF($B$4:$B$155,K8,$D$4:$D$155) -> 413860000 | M8: =SUMIF('Tháng 3 nhà T '!$B$4:$B$154,K8,'Tháng 3 nhà T '!$E$4:$E$154) -> 1.2814577e+08 | N8: =SUMIF('Tháng 3 nhà T '!$B$4:$B$154,K8,'Tháng 3 nhà T '!$F$4:$F$154) -> 74656331 | O8: =SUMIF('Tháng 3 nhà T '!$B$4:$B$154,K8,'Tháng 3 nhà T '!$G$4:$G$154) -> 4.5658185e+08
A9: T37 | B9: CHUNG | C9: 15 | D9: 10000000 | E9: 15110.9 | F9: -962843.68 | G9: =Table52111768152229343741465158916[[#This Row],[LỢI NHUẬN RÒNG]]+Table52111768152229343741465158916[[#This Row],[VỐN CP]] -> 9037156.3 | K9: HÀO | L9: =SUMIF($B$4:$B$155,K9,$D$4:$D$155) -> 68785000 | M9: =SUMIF('Tháng 3 nhà T '!$B$4:$B$154,K9,'Tháng 3 nhà T '!$E$4:$E$154) -> 26065061 | N9: =SUMIF('Tháng 3 nhà T '!$B$4:$B$154,K9,'Tháng 3 nhà T '!$F$4:$F$154) -> 15834008 | O9: =SUMIF('Tháng 3 nhà T '!$B$4:$B$154,K9,'Tháng 3 nhà T '!$G$4:$G$154) -> 84619008
A10: T37 | B10: ĐẠT | C10: 10 | D10: 6666666.7 | E10: 10073.933 | F10: -641895.79 | G10: =Table52111768152229343741465158916[[#This Row],[LỢI NHUẬN RÒNG]]+Table52111768152229343741465158916[[#This Row],[VỐN CP]] -> 6024770.9 | K10: HUY | L10: =SUMIF($B$4:$B$155,K10,$D$4:$D$155) -> 16000000 | M10: =SUMIF('Tháng 3 nhà T '!$B$4:$B$154,K10,'Tháng 3 nhà T '!$E$4:$E$154) -> 3927113.1 | N10: =SUMIF('Tháng 3 nhà T '!$B$4:$B$154,K10,'Tháng 3 nhà T '!$F$4:$F$154) -> 2336407.8 | O10: =SUMIF('Tháng 3 nhà T '!$B$4:$B$154,K10,'Tháng 3 nhà T '!$G$4:$G$154) -> 18336408
A11: T37 | B11: HẰNG | C11: 15 | D11: 10000000 | E11: 15110.9 | F11: -962843.68 | G11: =Table52111768152229343741465158916[[#This Row],[LỢI NHUẬN RÒNG]]+Table52111768152229343741465158916[[#This Row],[VỐN CP]] -> 9037156.3 | K11: KIÊN | L11: =SUMIF($B$4:$B$155,K11,$D$4:$D$155) -> 3.2734833e+08 | M11: =SUMIF('Tháng 3 nhà T '!$B$4:$B$154,K11,'Tháng 3 nhà T '!$E$4:$E$154) -> 1.0531641e+08 | N11: =SUMIF('Tháng 3 nhà T '!$B$4:$B$154,K11,'Tháng 3 nhà T '!$F$4:$F$154) -> 62076804 | O11: =SUMIF(Table52111768152229343741465158916[CỔ ĐÔNG],K11,Table52111768152229343741465158916[TỔNG NHẬN]) -> 3.8942514e+08
A12: T37 | B12: HÀO | C12: 10 | D12: 6666666.7 | E12: 10073.933 | F12: -641895.79 | G12: =Table52111768152229343741465158916[[#This Row],[LỢI NHUẬN RÒNG]]+Table52111768152229343741465158916[[#This Row],[VỐN CP]] -> 6024770.9 | K12: MẠNH | L12: =SUMIF($B$4:$B$155,K12,$D$4:$D$155) -> 44946667 | M12: =SUMIF('Tháng 3 nhà T '!$B$4:$B$154,K12,'Tháng 3 nhà T '!$E$4:$E$154) -> 10588585 | N12: =SUMIF('Tháng 3 nhà T '!$B$4:$B$154,K12,'Tháng 3 nhà T '!$F$4:$F$154) -> 5330265.9 | O12: =SUMIF('Tháng 3 nhà T '!$B$4:$B$154,K12,'Tháng 3 nhà T '!$G$4:$G$154) -> 50276933
A13: T37 | B13: KIÊN | C13: 10 | D13: 6666666.7 | E13: 10073.933 | F13: -641895.79 | G13: =Table52111768152229343741465158916[[#This Row],[LỢI NHUẬN RÒNG]]+Table52111768152229343741465158916[[#This Row],[VỐN CP]] -> 6024770.9 | K13: N. THẮNG | L13: =SUMIF($B$4:$B$155,K13,$D$4:$D$155) -> 8400000 | M13: =SUMIF('Tháng 3 nhà T '!$B$4:$B$154,K13,'Tháng 3 nhà T '!$E$4:$E$154) -> 4581122.5 | N13: =SUMIF('Tháng 3 nhà T '!$B$4:$B$154,K13,'Tháng 3 nhà T '!$F$4:$F$154) -> 3146163.2 | O13: =SUMIF('Tháng 3 nhà T '!$B$4:$B$154,K13,'Tháng 3 nhà T '!$G$4:$G$154) -> 11546163
A14: T37 | B14: MẠNH | C14: 10 | D14: 6666666.7 | E14: 10073.933 | F14: -641895.79 | G14: =Table52111768152229343741465158916[[#This Row],[LỢI NHUẬN RÒNG]]+Table52111768152229343741465158916[[#This Row],[VỐN CP]] -> 6024770.9 | K14: NGỌC | L14: =SUMIF($B$4:$B$155,K14,$D$4:$D$155) -> 17560000 | M14: =SUMIF('Tháng 3 nhà T '!$B$4:$B$154,K14,'Tháng 3 nhà T '!$E$4:$E$154) -> 4946809.6 | N14: =SUMIF('Tháng 3 nhà T '!$B$4:$B$154,K14,'Tháng 3 nhà T '!$F$4:$F$154) -> 2648469.1 | O14: =SUMIF('Tháng 3 nhà T '!$B$4:$B$154,K14,'Tháng 3 nhà T '!$G$4:$G$154) -> 20208469
A15: T37 | B15: TÙNG | C15: 20 | D15: 13333333 | E15: 20147.867 | F15: -1283791.6 | G15: =Table52111768152229343741465158916[[#This Row],[LỢI NHUẬN RÒNG]]+Table52111768152229343741465158916[[#This Row],[VỐN CP]] -> 12049542 | K15: TÙNG | L15: =SUMIF($B$4:$B$155,K15,$D$4:$D$155) -> 42353333 | M15: =SUMIF('Tháng 3 nhà T '!$B$4:$B$154,K15,'Tháng 3 nhà T '!$E$4:$E$154) -> 4417204 | N15: =SUMIF('Tháng 3 nhà T '!$B$4:$B$154,K15,'Tháng 3 nhà T '!$F$4:$F$154) -> -847234.57 | O15: =SUMIF('Tháng 3 nhà T '!$B$4:$B$154,K15,'Tháng 3 nhà T '!$G$4:$G$154) -> 41506099
A16: T38 | B16: CHUNG | C16: 30 | D16: 7950000 | E16: 3140702.7 | F16: 1510924.4 | G16: =Table52111768152229343741465158916[[#This Row],[LỢI NHUẬN RÒNG]]+Table52111768152229343741465158916[[#This Row],[VỐN CP]] -> 9460924.4 | K16: HUY ANH | L16: =SUMIF($B$4:$B$155,K16,$D$4:$D$155) -> 2750000 | M16: =SUMIF('Tháng 3 nhà T '!$B$4:$B$154,K16,'Tháng 3 nhà T '!$E$4:$E$154) -> 275458.4 | N16: =SUMIF('Tháng 3 nhà T '!$B$4:$B$154,K16,'Tháng 3 nhà T '!$F$4:$F$154) -> -189202.39 | O16: =SUMIF('Tháng 3 nhà T '!$B$4:$B$154,K16,'Tháng 3 nhà T '!$G$4:$G$154) -> 2560797.6
A17: T38 | B17: HẰNG | C17: 30 | D17: 7950000 | E17: 3140702.7 | F17: 1510924.4 | G17: =Table52111768152229343741465158916[[#This Row],[LỢI NHUẬN RÒNG]]+Table52111768152229343741465158916[[#This Row],[VỐN CP]] -> 9460924.4 | K17: TỔNG | L17: =SUM(L2:L16) -> 1.4740167e+09 | M17: =SUM(M2:M16) -> 445543726 | N17: =SUM(N2:N16) -> 2.5434847e+08 | O17: =SUM(O2:O16) -> 1.6964307e+09
A18: T38 | B18: HÀO | C18: 10 | D18: 2650000 | E18: 1046900.9 | F18: 503641.45 | G18: =Table52111768152229343741465158916[[#This Row],[LỢI NHUẬN RÒNG]]+Table52111768152229343741465158916[[#This Row],[VỐN CP]] -> 3153641.5
A19: T38 | B19: KIÊN | C19: 20 | D19: 5300000 | E19: 2093801.8 | F19: 1007282.9 | G19: =Table52111768152229343741465158916[[#This Row],[LỢI NHUẬN RÒNG]]+Table52111768152229343741465158916[[#This Row],[VỐN CP]] -> 6307282.9
A20: T38 | B20: NGỌC | C20: 10 | D20: 2650000 | E20: 1046900.9 | F20: 503641.45 | G20: =Table52111768152229343741465158916[[#This Row],[LỢI NHUẬN RÒNG]]+Table52111768152229343741465158916[[#This Row],[VỐN CP]] -> 3153641.5
A21: T41 | B21: CHUNG | C21: 25 | D21: 13750000 | E21: 1377292 | F21: -946011.94 | G21: =Table52111768152229343741465158916[[#This Row],[LỢI NHUẬN RÒNG]]+Table52111768152229343741465158916[[#This Row],[VỐN CP]] -> 12803988
A22: T41 | B22: HẰNG | C22: 25 | D22: 13750000 | E22: 1377292 | F22: -946011.94 | G22: =Table52111768152229343741465158916[[#This Row],[LỢI NHUẬN RÒNG]]+Table52111768152229343741465158916[[#This Row],[VỐN CP]] -> 12803988
A23: T41 | B23: HUY ANH | C23: 5 | D23: 2750000 | E23: 275458.4 | F23: -189202.39 | G23: =Table52111768152229343741465158916[[#This Row],[LỢI NHUẬN RÒNG]]+Table52111768152229343741465158916[[#This Row],[VỐN CP]] -> 2560797.6
A24: T41 | B24: NGỌC | C24: 5 | D24: 2750000 | E24: 275458.4 | F24: -189202.39 | G24: =Table52111768152229343741465158916[[#This Row],[LỢI NHUẬN RÒNG]]+Table52111768152229343741465158916[[#This Row],[VỐN CP]] -> 2560797.6
A25: T41 | B25: KIÊN | C25: 20 | D25: 11000000 | E25: 1101833.6 | F25: -756809.55 | G25: =Table52111768152229343741465158916[[#This Row],[LỢI NHUẬN RÒNG]]+Table52111768152229343741465158916[[#This Row],[VỐN CP]] -> 10243190
A26: T41 | B26: MẠNH | C26: 10 | D26: 5500000 | E26: 550916.8 | F26: -378404.77 | G26: =Table52111768152229343741465158916[[#This Row],[LỢI NHUẬN RÒNG]]+Table52111768152229343741465158916[[#This Row],[VỐN CP]] -> 5121595.2
A27: T42 | B27: CHUNG | C27: 35 | D27: 45237500 | E27: 14223290 | F27: 7779909 | G27: =Table52111768152229343741465158916[[#This Row],[LỢI NHUẬN RÒNG]]+Table52111768152229343741465158916[[#This Row],[VỐN CP]] -> 53017409
A28: T42 | B28: HẰNG | C28: 40 | D28: 51700000 | E28: 16255189 | F28: 8891324.5 | G28: =Table52111768152229343741465158916[[#This Row],[LỢI NHUẬN RÒNG]]+Table52111768152229343741465158916[[#This Row],[VỐN CP]] -> 60591325
A29: T42 | B29: HÀO | C29: 10 | D29: 12925000 | E29: 4063797.2 | F29: 2222831.1 | G29: =Table52111768152229343741465158916[[#This Row],[LỢI NHUẬN RÒNG]]+Table52111768152229343741465158916[[#This Row],[VỐN CP]] -> 15147831
... A88: T25 | B88: CHUNG | C88: 30 | D88: 33000000 | E88: 11849489 | F88: 5321376.4 | G88: =Table52111768152229343741465158916[[#This Row],[LỢI NHUẬN RÒNG]]+Table52111768152229343741465158916[[#This Row],[VỐN CP]] -> 38321376
A89: T25 | B89: HẰNG | C89: 25 | D89: 27500000 | E89: 9874574 | F89: 4434480.3
A90: T25 | B90: HÀO | C90: 15 | D90: 16500000 | E90: 5924744.4 | F90: 2660688.2 | G90: =Table52111768152229343741465158916[[#This Row],[LỢI NHUẬN RÒNG]]+Table52111768152229343741465158916[[#This Row],[VỐN CP]] -> 19160688
A91: T25 | B91: KIÊN | C91: 20 | D91: 22000000 | E91: 7899659.2 | F91: 3547584.3 | G91: =Table52111768152229343741465158916[[#This Row],[LỢI NHUẬN RÒNG]]+Table52111768152229343741465158916[[#This Row],[VỐN CP]] -> 25547584
A92: T25 | B92: TÙNG | C92: 10 | D92: 11000000 | E92: 3949829.6 | F92: 1773792.1 | G92: =Table52111768152229343741465158916[[#This Row],[LỢI NHUẬN RÒNG]]+Table52111768152229343741465158916[[#This Row],[VỐN CP]] -> 12773792
A93: T26 | B93: CHUNG | C93: 25 | D93: 12500000 | E93: -1387007.8 | F93: -2307284.6 | G93: =Table52111768152229343741465158916[[#This Row],[LỢI NHUẬN RÒNG]]+Table52111768152229343741465158916[[#This Row],[VỐN CP]] -> 10192715
A94: T26 | B94: HẰNG | C94: 25 | D94: 12500000 | E94: -1387007.8 | F94: -2307284.6 | G94: =Table52111768152229343741465158916[[#This Row],[LỢI NHUẬN RÒNG]]+Table52111768152229343741465158916[[#This Row],[VỐN CP]] -> 10192715
A95: T26 | B95: HUY | C95: 10 | D95: 5000000 | E95: -554803.1 | F95: -922913.84 | G95: =Table52111768152229343741465158916[[#This Row],[LỢI NHUẬN RÒNG]]+Table52111768152229343741465158916[[#This Row],[VỐN CP]] -> 4077086.2
A96: T26 | B96: KIÊN | C96: 40 | D96: 20000000 | E96: -2219212.4 | F96: -3691655.4 | G96: =Table52111768152229343741465158916[[#This Row],[LỢI NHUẬN RÒNG]]+Table52111768152229343741465158916[[#This Row],[VỐN CP]] -> 16308345
A97: T27 | B97: CHUNG | C97: 25 | D97: 14400000 | E97: -4236217.8 | F97: -5319763.1 | G97: =Table52111768152229343741465158916[[#This Row],[LỢI NHUẬN RÒNG]]+Table52111768152229343741465158916[[#This Row],[VỐN CP]] -> 9080236.9
A98: T27 | B98: Đ. THẮNG | C98: 10 | D98: 5760000 | E98: -1694487.1 | F98: -2127905.2 | G98: =Table52111768152229343741465158916[[#This Row],[LỢI NHUẬN RÒNG]]+Table52111768152229343741465158916[[#This Row],[VỐN CP]] -> 3632094.8
...

Sheet Tháng 2 nhà T   
A1: BẢNG CHIA CỔ PHẦN THÁNG 2.26 NHÀ T
K2: CỔ ĐÔNG | L2: VỐN CP | M2: LỢI NHUẬN GỘP | N2: LỢI NHUẬN RÒNG | O2: TỔNG NHẬN
A3: MÃ TOÀ | B3: CỔ ĐÔNG | C3: TỈ LỆ % | D3: VỐN CP | E3: LỢI NHUẬN GỘP | F3: LỢI NHUẬN RÒNG | G3: TỔNG NHẬN | K3: A ĐIỆP | L3: =SUMIF($B$4:$B$155,K3,$D$4:$D$155) -> 21095833 | M3: =SUMIF('Tháng 2 nhà T '!$B$4:$B$154,K3,'Tháng 2 nhà T '!$E$4:$E$154) -> 3296597.3 | N3: =SUMIF('Tháng 2 nhà T '!$B$4:$B$154,K3,'Tháng 2 nhà T '!$F$4:$F$154) -> 302008.18 | O3: =SUMIF('Tháng 2 nhà T '!$B$4:$B$154,K3,'Tháng 2 nhà T '!$G$4:$G$154) -> 21397842
A4: T33 | B4: CHUNG | C4: 30 | D4: 13200000 | E4: 3867807.3 | F4: 2179906.9 | G4: =Table521117681522293437414651589[[#This Row],[LỢI NHUẬN RÒNG]]+Table521117681522293437414651589[[#This Row],[VỐN CP]] -> 15379907 | K4: CHIẾN | L4: =SUMIF($B$4:$B$155,K4,$D$4:$D$155) -> 81893333 | M4: =SUMIF('Tháng 2 nhà T '!$B$4:$B$154,K4,'Tháng 2 nhà T '!$E$4:$E$154) -> 19091323 | N4: =SUMIF('Tháng 2 nhà T '!$B$4:$B$154,K4,'Tháng 2 nhà T '!$F$4:$F$154) -> 8175394.1 | O4: =SUMIF('Tháng 2 nhà T '!$B$4:$B$154,K4,'Tháng 2 nhà T '!$G$4:$G$154) -> 90068727
A5: T33 | B5: HẰNG | C5: 30 | D5: 13200000 | E5: 3867807.3 | F5: 2179906.9 | G5: =Table521117681522293437414651589[[#This Row],[LỢI NHUẬN RÒNG]]+Table521117681522293437414651589[[#This Row],[VỐN CP]] -> 15379907 | K5: CHUNG | L5: =SUMIF($B$4:$B$155,K5,$D$4:$D$155) -> 4.1166417e+08 | M5: =SUMIF('Tháng 2 nhà T '!$B$4:$B$154,K5,'Tháng 2 nhà T '!$E$4:$E$154) -> 1.112711e+08 | N5: =SUMIF('Tháng 2 nhà T '!$B$4:$B$154,K5,'Tháng 2 nhà T '!$F$4:$F$154) -> 48313062 | O5: =SUMIF('Tháng 2 nhà T '!$B$4:$B$154,K5,'Tháng 2 nhà T '!$G$4:$G$154) -> 4.5997723e+08
A6: T33 | B6: HÀO | C6: 10 | D6: 4400000 | E6: 1289269.1 | F6: 726635.63 | G6: =Table521117681522293437414651589[[#This Row],[LỢI NHUẬN RÒNG]]+Table521117681522293437414651589[[#This Row],[VỐN CP]] -> 5126635.6 | K6: Đ. THẮNG | L6: =SUMIF($B$4:$B$155,K6,$D$4:$D$155) -> 10693333 | M6: =SUMIF('Tháng 2 nhà T '!$B$4:$B$154,K6,'Tháng 2 nhà T '!$E$4:$E$154) -> 15215.667 | N6: =SUMIF('Tháng 2 nhà T '!$B$4:$B$154,K6,'Tháng 2 nhà T '!$F$4:$F$154) -> -1196273.2 | O6: =SUMIF('Tháng 2 nhà T '!$B$4:$B$154,K6,'Tháng 2 nhà T '!$G$4:$G$154) -> 9497060.1
A7: T33 | B7: KIÊN | C7: 20 | D7: 8800000 | E7: 2578538.2 | F7: 1453271.3 | G7: =Table521117681522293437414651589[[#This Row],[LỢI NHUẬN RÒNG]]+Table521117681522293437414651589[[#This Row],[VỐN CP]] -> 10253271 | K7: ĐẠT | L7: =SUMIF($B$4:$B$155,K7,$D$4:$D$155) -> 6666666.7 | M7: =SUMIF('Tháng 2 nhà T '!$B$4:$B$154,K7,'Tháng 2 nhà T '!$E$4:$E$154) -> 257309.63 | N7: =SUMIF('Tháng 2 nhà T '!$B$4:$B$154,K7,'Tháng 2 nhà T '!$F$4:$F$154) -> -526885.54 | O7: =SUMIF('Tháng 2 nhà T '!$B$4:$B$154,K7,'Tháng 2 nhà T '!$G$4:$G$154) -> 6139781.1
A8: T33 | B8: MẠNH | C8: 10 | D8: 4400000 | E8: 1289269.1 | F8: 726635.63 | G8: =Table521117681522293437414651589[[#This Row],[LỢI NHUẬN RÒNG]]+Table521117681522293437414651589[[#This Row],[VỐN CP]] -> 5126635.6 | K8: HẰNG | L8: =SUMIF($B$4:$B$155,K8,$D$4:$D$155) -> 413860000 | M8: =SUMIF('Tháng 2 nhà T '!$B$4:$B$154,K8,'Tháng 2 nhà T '!$E$4:$E$154) -> 1.1159478e+08 | N8: =SUMIF('Tháng 2 nhà T '!$B$4:$B$154,K8,'Tháng 2 nhà T '!$F$4:$F$154) -> 48243009 | O8: =SUMIF('Tháng 2 nhà T '!$B$4:$B$154,K8,'Tháng 2 nhà T '!$G$4:$G$154) -> 4.2957753e+08
A9: T37 | B9: CHUNG | C9: 15 | D9: 10000000 | E9: 385964.45 | F9: -790328.31 | G9: =Table521117681522293437414651589[[#This Row],[LỢI NHUẬN RÒNG]]+Table521117681522293437414651589[[#This Row],[VỐN CP]] -> 9209671.7 | K9: HÀO | L9: =SUMIF($B$4:$B$155,K9,$D$4:$D$155) -> 68785000 | M9: =SUMIF('Tháng 2 nhà T '!$B$4:$B$154,K9,'Tháng 2 nhà T '!$E$4:$E$154) -> 23833538 | N9: =SUMIF('Tháng 2 nhà T '!$B$4:$B$154,K9,'Tháng 2 nhà T '!$F$4:$F$154) -> 12666249 | O9: =SUMIF('Tháng 2 nhà T '!$B$4:$B$154,K9,'Tháng 2 nhà T '!$G$4:$G$154) -> 81451249
A10: T37 | B10: ĐẠT | C10: 10 | D10: 6666666.7 | E10: 257309.63 | F10: -526885.54 | G10: =Table521117681522293437414651589[[#This Row],[LỢI NHUẬN RÒNG]]+Table521117681522293437414651589[[#This Row],[VỐN CP]] -> 6139781.1 | K10: HUY | L10: =SUMIF($B$4:$B$155,K10,$D$4:$D$155) -> 16000000 | M10: =SUMIF('Tháng 2 nhà T '!$B$4:$B$154,K10,'Tháng 2 nhà T '!$E$4:$E$154) -> 4000954.7 | N10: =SUMIF('Tháng 2 nhà T '!$B$4:$B$154,K10,'Tháng 2 nhà T '!$F$4:$F$154) -> 1211547.1 | O10: =SUMIF('Tháng 2 nhà T '!$B$4:$B$154,K10,'Tháng 2 nhà T '!$G$4:$G$154) -> 17211547
A11: T37 | B11: HẰNG | C11: 15 | D11: 10000000 | E11: 385964.45 | F11: -790328.31 | G11: =Table521117681522293437414651589[[#This Row],[LỢI NHUẬN RÒNG]]+Table521117681522293437414651589[[#This Row],[VỐN CP]] -> 9209671.7 | K11: KIÊN | L11: =SUMIF($B$4:$B$155,K11,$D$4:$D$155) -> 3.2734833e+08 | M11: =SUMIF('Tháng 2 nhà T '!$B$4:$B$154,K11,'Tháng 2 nhà T '!$E$4:$E$154) -> 92620924 | N11: =SUMIF('Tháng 2 nhà T '!$B$4:$B$154,K11,'Tháng 2 nhà T '!$F$4:$F$154) -> 41522857 | O11: =SUMIF(Table521117681522293437414651589[CỔ ĐÔNG],K11,Table521117681522293437414651589[TỔNG NHẬN]) -> 3.6887119e+08
A12: T37 | B12: HÀO | C12: 10 | D12: 6666666.7 | E12: 257309.63 | F12: -526885.54 | G12: =Table521117681522293437414651589[[#This Row],[LỢI NHUẬN RÒNG]]+Table521117681522293437414651589[[#This Row],[VỐN CP]] -> 6139781.1 | K12: MẠNH | L12: =SUMIF($B$4:$B$155,K12,$D$4:$D$155) -> 44946667 | M12: =SUMIF('Tháng 2 nhà T '!$B$4:$B$154,K12,'Tháng 2 nhà T '!$E$4:$E$154) -> 8198456.3 | N12: =SUMIF('Tháng 2 nhà T '!$B$4:$B$154,K12,'Tháng 2 nhà T '!$F$4:$F$154) -> 2309606.8 | O12: =SUMIF('Tháng 2 nhà T '!$B$4:$B$154,K12,'Tháng 2 nhà T '!$G$4:$G$154) -> 47256273
A13: T37 | B13: KIÊN | C13: 10 | D13: 6666666.7 | E13: 257309.63 | F13: -526885.54 | G13: =Table521117681522293437414651589[[#This Row],[LỢI NHUẬN RÒNG]]+Table521117681522293437414651589[[#This Row],[VỐN CP]] -> 6139781.1 | K13: N. THẮNG | L13: =SUMIF($B$4:$B$155,K13,$D$4:$D$155) -> 8400000 | M13: =SUMIF('Tháng 2 nhà T '!$B$4:$B$154,K13,'Tháng 2 nhà T '!$E$4:$E$154) -> 4187536.4 | N13: =SUMIF('Tháng 2 nhà T '!$B$4:$B$154,K13,'Tháng 2 nhà T '!$F$4:$F$154) -> 2483078.8 | O13: =SUMIF('Tháng 2 nhà T '!$B$4:$B$154,K13,'Tháng 2 nhà T '!$G$4:$G$154) -> 10883079
A14: T37 | B14: MẠNH | C14: 10 | D14: 6666666.7 | E14: 257309.63 | F14: -526885.54 | G14: =Table521117681522293437414651589[[#This Row],[LỢI NHUẬN RÒNG]]+Table521117681522293437414651589[[#This Row],[VỐN CP]] -> 6139781.1 | K14: NGỌC | L14: =SUMIF($B$4:$B$155,K14,$D$4:$D$155) -> 17560000 | M14: =SUMIF('Tháng 2 nhà T '!$B$4:$B$154,K14,'Tháng 2 nhà T '!$E$4:$E$154) -> 2976088.5 | N14: =SUMIF('Tháng 2 nhà T '!$B$4:$B$154,K14,'Tháng 2 nhà T '!$F$4:$F$154) -> 405830.75 | O14: =SUMIF('Tháng 2 nhà T '!$B$4:$B$154,K14,'Tháng 2 nhà T '!$G$4:$G$154) -> 17965831
A15: T37 | B15: TÙNG | C15: 20 | D15: 13333333 | E15: 514619.27 | F15: -1053771.1 | G15: =Table521117681522293437414651589[[#This Row],[LỢI NHUẬN RÒNG]]+Table521117681522293437414651589[[#This Row],[VỐN CP]] -> 12279562 | K15: TÙNG | L15: =SUMIF($B$4:$B$155,K15,$D$4:$D$155) -> 42353333 | M15: =SUMIF('Tháng 2 nhà T '!$B$4:$B$154,K15,'Tháng 2 nhà T '!$E$4:$E$154) -> 6838635.6 | N15: =SUMIF('Tháng 2 nhà T '!$B$4:$B$154,K15,'Tháng 2 nhà T '!$F$4:$F$154) -> 1052908.5 | O15: =SUMIF('Tháng 2 nhà T '!$B$4:$B$154,K15,'Tháng 2 nhà T '!$G$4:$G$154) -> 43406242
A16: T38 | B16: CHUNG | C16: 30 | D16: 7950000 | E16: -1155073.5 | F16: -1966875.6 | G16: =Table521117681522293437414651589[[#This Row],[LỢI NHUẬN RÒNG]]+Table521117681522293437414651589[[#This Row],[VỐN CP]] -> 5983124.4 | K16: HUY ANH | L16: =SUMIF($B$4:$B$155,K16,$D$4:$D$155) -> 2750000 | M16: =SUMIF('Tháng 2 nhà T '!$B$4:$B$154,K16,'Tháng 2 nhà T '!$E$4:$E$154) -> 322600.45 | N16: =SUMIF('Tháng 2 nhà T '!$B$4:$B$154,K16,'Tháng 2 nhà T '!$F$4:$F$154) -> 952.62196 | O16: =SUMIF('Tháng 2 nhà T '!$B$4:$B$154,K16,'Tháng 2 nhà T '!$G$4:$G$154) -> 2750952.6
A17: T38 | B17: HẰNG | C17: 30 | D17: 7950000 | E17: -1155073.5 | F17: -1966875.6 | G17: =Table521117681522293437414651589[[#This Row],[LỢI NHUẬN RÒNG]]+Table521117681522293437414651589[[#This Row],[VỐN CP]] -> 5983124.4 | K17: TỔNG | L17: =SUM(L2:L16) -> 1.4740167e+09 | M17: =SUM(M2:M16) -> 3.8850506e+08 | N17: =SUM(N2:N16) -> 1.6496335e+08 | O17: =SUM(O2:O16) -> 1.6064545e+09
A18: T38 | B18: HÀO | C18: 10 | D18: 2650000 | E18: -385024.5 | F18: -655625.21 | G18: =Table521117681522293437414651589[[#This Row],[LỢI NHUẬN RÒNG]]+Table521117681522293437414651589[[#This Row],[VỐN CP]] -> 1994374.8
A19: T38 | B19: KIÊN | C19: 20 | D19: 5300000 | E19: -770049 | F19: -1311250.4 | G19: =Table521117681522293437414651589[[#This Row],[LỢI NHUẬN RÒNG]]+Table521117681522293437414651589[[#This Row],[VỐN CP]] -> 3988749.6
A20: T38 | B20: NGỌC | C20: 10 | D20: 2650000 | E20: -385024.5 | F20: -655625.21 | G20: =Table521117681522293437414651589[[#This Row],[LỢI NHUẬN RÒNG]]+Table521117681522293437414651589[[#This Row],[VỐN CP]] -> 1994374.8
A21: T41 | B21: CHUNG | C21: 25 | D21: 13750000 | E21: 1613002.2 | F21: 4763.1098 | G21: =Table521117681522293437414651589[[#This Row],[LỢI NHUẬN RÒNG]]+Table521117681522293437414651589[[#This Row],[VỐN CP]] -> 13754763
A22: T41 | B22: HẰNG | C22: 25 | D22: 13750000 | E22: 1613002.2 | F22: 4763.1098 | G22: =Table521117681522293437414651589[[#This Row],[LỢI NHUẬN RÒNG]]+Table521117681522293437414651589[[#This Row],[VỐN CP]] -> 13754763
A23: T41 | B23: HUY ANH | C23: 5 | D23: 2750000 | E23: 322600.45 | F23: 952.62196 | G23: =Table521117681522293437414651589[[#This Row],[LỢI NHUẬN RÒNG]]+Table521117681522293437414651589[[#This Row],[VỐN CP]] -> 2750952.6
A24: T41 | B24: NGỌC | C24: 5 | D24: 2750000 | E24: 322600.45 | F24: 952.62196 | G24: =Table521117681522293437414651589[[#This Row],[LỢI NHUẬN RÒNG]]+Table521117681522293437414651589[[#This Row],[VỐN CP]] -> 2750952.6
A25: T41 | B25: KIÊN | C25: 20 | D25: 11000000 | E25: 1290401.8 | F25: 3810.4878 | G25: =Table521117681522293437414651589[[#This Row],[LỢI NHUẬN RÒNG]]+Table521117681522293437414651589[[#This Row],[VỐN CP]] -> 11003810
A26: T41 | B26: MẠNH | C26: 10 | D26: 5500000 | E26: 645200.9 | F26: 1905.2439 | G26: =Table521117681522293437414651589[[#This Row],[LỢI NHUẬN RÒNG]]+Table521117681522293437414651589[[#This Row],[VỐN CP]] -> 5501905.2
A27: T42 | B27: CHUNG | C27: 35 | D27: 45237500 | E27: 16106020 | F27: 7301683.2 | G27: =Table521117681522293437414651589[[#This Row],[LỢI NHUẬN RÒNG]]+Table521117681522293437414651589[[#This Row],[VỐN CP]] -> 52539183
A28: T42 | B28: HẰNG | C28: 40 | D28: 51700000 | E28: 18406880 | F28: 8344780.9 | G28: =Table521117681522293437414651589[[#This Row],[LỢI NHUẬN RÒNG]]+Table521117681522293437414651589[[#This Row],[VỐN CP]] -> 60044781
A29: T42 | B29: HÀO | C29: 10 | D29: 12925000 | E29: 4601720 | F29: 2086195.2 | G29: =Table521117681522293437414651589[[#This Row],[LỢI NHUẬN RÒNG]]+Table521117681522293437414651589[[#This Row],[VỐN CP]] -> 15011195
... A88: T25 | B88: CHUNG | C88: 30 | D88: 33000000 | E88: 12142791 | F88: 6030575.2 | G88: =Table521117681522293437414651589[[#This Row],[LỢI NHUẬN RÒNG]]+Table521117681522293437414651589[[#This Row],[VỐN CP]] -> 39030575
A89: T25 | B89: HẰNG | C89: 25 | D89: 27500000 | E89: 10118992 | F89: 5025479.3
A90: T25 | B90: HÀO | C90: 15 | D90: 16500000 | E90: 6071395.3 | F90: 3015287.6 | G90: =Table521117681522293437414651589[[#This Row],[LỢI NHUẬN RÒNG]]+Table521117681522293437414651589[[#This Row],[VỐN CP]] -> 19515288
A91: T25 | B91: KIÊN | C91: 20 | D91: 22000000 | E91: 8095193.8 | F91: 4020383.4 | G91: =Table521117681522293437414651589[[#This Row],[LỢI NHUẬN RÒNG]]+Table521117681522293437414651589[[#This Row],[VỐN CP]] -> 26020383
A92: T25 | B92: TÙNG | C92: 10 | D92: 11000000 | E92: 4047596.9 | F92: 2010191.7 | G92: =Table521117681522293437414651589[[#This Row],[LỢI NHUẬN RÒNG]]+Table521117681522293437414651589[[#This Row],[VỐN CP]] -> 13010192
A93: T26 | B93: CHUNG | C93: 25 | D93: 12500000 | E93: 2030966.2 | F93: 581595.37 | G93: =Table521117681522293437414651589[[#This Row],[LỢI NHUẬN RÒNG]]+Table521117681522293437414651589[[#This Row],[VỐN CP]] -> 13081595
A94: T26 | B94: HẰNG | C94: 25 | D94: 12500000 | E94: 2030966.2 | F94: 581595.37 | G94: =Table521117681522293437414651589[[#This Row],[LỢI NHUẬN RÒNG]]+Table521117681522293437414651589[[#This Row],[VỐN CP]] -> 13081595
A95: T26 | B95: HUY | C95: 10 | D95: 5000000 | E95: 812386.5 | F95: 232638.15 | G95: =Table521117681522293437414651589[[#This Row],[LỢI NHUẬN RÒNG]]+Table521117681522293437414651589[[#This Row],[VỐN CP]] -> 5232638.1
A96: T26 | B96: KIÊN | C96: 40 | D96: 20000000 | E96: 3249546 | F96: 930552.6 | G96: =Table521117681522293437414651589[[#This Row],[LỢI NHUẬN RÒNG]]+Table521117681522293437414651589[[#This Row],[VỐN CP]] -> 20930553
A97: T27 | B97: CHUNG | C97: 25 | D97: 14400000 | E97: -428094.5 | F97: -1910137.4 | G97: =Table521117681522293437414651589[[#This Row],[LỢI NHUẬN RÒNG]]+Table521117681522293437414651589[[#This Row],[VỐN CP]] -> 12489863
A98: T27 | B98: Đ. THẮNG | C98: 10 | D98: 5760000 | E98: -171237.8 | F98: -764054.96 | G98: =Table521117681522293437414651589[[#This Row],[LỢI NHUẬN RÒNG]]+Table521117681522293437414651589[[#This Row],[VỐN CP]] -> 4995945
...

Sheet Tháng 2 nhà S 
A1: BẢNG CHIA CỔ PHẦN THÁNG 2.26 NHÀ S
A2: MÃ TOÀ | B2: CỔ ĐÔNG | C2: TỈ LỆ % | D2: VỐN CP | E2: LỢI NHUẬN GỘP | F2: LỢI NHUẬN RÒNG | G2: TỔNG NHẬN | H2: Column1 | K2: CỔ ĐÔNG | L2: VỐN CP | M2: LỢI NHUẬN GỘP | N2: LỢI NHUẬN RÒNG | O2: TỔNG NHẬN
A3: S1 | B3: CHUNG | C3: 35 | D3: 8400000 | E3: 2699876.9 | F3: 1498794.8 | G3: =D3+Table8414194101324273239434853567[[#This Row],[LỢI NHUẬN RÒNG]] -> 9898794.8 | K3: A ĐIỆP | L3: =SUMIF(Table8414194101324273239434853567[CỔ ĐÔNG],K3,Table8414194101324273239434853567[VỐN CP]) -> 48688333 | M3: =SUMIF(Table8414194101324273239434853567[CỔ ĐÔNG],K3,Table8414194101324273239434853567[LỢI NHUẬN GỘP]) -> 12343076 | N3: =SUMIF(Table8414194101324273239434853567[CỔ ĐÔNG],K3,Table8414194101324273239434853567[LỢI NHUẬN RÒNG]) -> 4971476.3 | O3: =SUMIF(Table8414194101324273239434853567[CỔ ĐÔNG],K3,Table8414194101324273239434853567[TỔNG NHẬN]) -> 53659810
A4: S2 | B4: CHUNG | C4: 35 | D4: 17266667 | E4: 1762619.5 | F4: -605414.04 | G4: =D4+Table8414194101324273239434853567[[#This Row],[LỢI NHUẬN RÒNG]] -> 16661253 | K4: CHUNG | L4: =SUMIF(Table8414194101324273239434853567[CỔ ĐÔNG],K4,Table8414194101324273239434853567[VỐN CP]) -> 3.7464667e+08 | M4: =SUMIF(Table8414194101324273239434853567[CỔ ĐÔNG],K4,Table8414194101324273239434853567[LỢI NHUẬN GỘP]) -> 95972356 | N4: =SUMIF(Table8414194101324273239434853567[CỔ ĐÔNG],K4,Table8414194101324273239434853567[LỢI NHUẬN RÒNG]) -> 41362761 | O4: =SUMIF(Table8414194101324273239434853567[CỔ ĐÔNG],Table9515205111425283340444954578[[#This Row],[CỔ ĐÔNG]],Table8414194101324273239434853567[TỔNG NHẬN]) -> 4.1616748e+08
A5: S3 | B5: CHUNG | C5: 30 | D5: 12600000 | E5: 3784934.7 | F5: 2039698.9 | G5: =D5+Table8414194101324273239434853567[[#This Row],[LỢI NHUẬN RÒNG]] -> 14639699 | K5: Đ.THẮNG | L5: =SUMIF(Table8414194101324273239434853567[CỔ ĐÔNG],K5,Table8414194101324273239434853567[VỐN CP]) -> 63601667 | M5: =SUMIF(Table8414194101324273239434853567[CỔ ĐÔNG],K5,Table8414194101324273239434853567[LỢI NHUẬN GỘP]) -> 16795114 | N5: =SUMIF(Table8414194101324273239434853567[CỔ ĐÔNG],K5,Table8414194101324273239434853567[LỢI NHUẬN RÒNG]) -> 7362491.7 | O5: =SUMIF(Table8414194101324273239434853567[CỔ ĐÔNG],Table9515205111425283340444954578[[#This Row],[CỔ ĐÔNG]],Table8414194101324273239434853567[TỔNG NHẬN]) -> 71016842
A6: S4 | B6: CHUNG | C6: 30 | D6: 15900000 | E6: 5038017.6 | F6: 2494556.9 | G6: =D6+Table8414194101324273239434853567[[#This Row],[LỢI NHUẬN RÒNG]] -> 18394557 | K6: ĐẠT | L6: =SUMIF(Table8414194101324273239434853567[CỔ ĐÔNG],K6,Table8414194101324273239434853567[VỐN CP]) -> 28546667 | M6: =SUMIF(Table8414194101324273239434853567[CỔ ĐÔNG],K6,Table8414194101324273239434853567[LỢI NHUẬN GỘP]) -> 9653865.6 | N6: =SUMIF(Table8414194101324273239434853567[CỔ ĐÔNG],K6,Table8414194101324273239434853567[LỢI NHUẬN RÒNG]) -> 4913519.3 | O6: =SUMIF(Table8414194101324273239434853567[CỔ ĐÔNG],K6,Table8414194101324273239434853567[TỔNG NHẬN]) -> 33460186
A7: S5 | B7: CHUNG | C7: 40 | D7: 18000000 | E7: 930425.6 | F7: -1678541 | G7: =D7+Table8414194101324273239434853567[[#This Row],[LỢI NHUẬN RÒNG]] -> 16321459 | K7: DT | L7: =SUMIF(Table8414194101324273239434853567[CỔ ĐÔNG],K7,Table8414194101324273239434853567[VỐN CP]) -> 6795000 | M7: =SUMIF(Table8414194101324273239434853567[CỔ ĐÔNG],K7,Table8414194101324273239434853567[LỢI NHUẬN GỘP]) -> 3212108.5 | N7: =SUMIF(Table8414194101324273239434853567[CỔ ĐÔNG],K7,Table8414194101324273239434853567[LỢI NHUẬN RÒNG]) -> 2038490.8 | O7: =SUMIF(Table8414194101324273239434853567[CỔ ĐÔNG],Table9515205111425283340444954578[[#This Row],[CỔ ĐÔNG]],Table8414194101324273239434853567[TỔNG NHẬN]) -> 8833490.8
A8: S6 | B8: CHUNG | C8: 25 | D8: 8250000 | E8: 2363969 | F8: 1272745.6 | G8: =D8+Table8414194101324273239434853567[[#This Row],[LỢI NHUẬN RÒNG]] -> 9522745.6 | K8: HẰNG | L8: =SUMIF(Table8414194101324273239434853567[CỔ ĐÔNG],K8,Table8414194101324273239434853567[VỐN CP]) -> 3.9149333e+08 | M8: =SUMIF(Table8414194101324273239434853567[CỔ ĐÔNG],K8,Table8414194101324273239434853567[LỢI NHUẬN GỘP]) -> 89266655 | N8: =SUMIF(Table8414194101324273239434853567[CỔ ĐÔNG],K8,Table8414194101324273239434853567[LỢI NHUẬN RÒNG]) -> 32589123 | O8: =SUMIF(Table8414194101324273239434853567[CỔ ĐÔNG],Table9515205111425283340444954578[[#This Row],[CỔ ĐÔNG]],Table8414194101324273239434853567[TỔNG NHẬN]) -> 4.2424051e+08
A9: S7 | B9: CHUNG | C9: 25 | D9: 9000000 | E9: 1802932.8 | F9: 415580.63 | G9: =D9+Table8414194101324273239434853567[[#This Row],[LỢI NHUẬN RÒNG]] -> 9415580.6 | K9: HÀO | L9: =SUMIF(Table8414194101324273239434853567[CỔ ĐÔNG],K9,Table8414194101324273239434853567[VỐN CP]) -> 3.4534833e+08 | M9: =SUMIF(Table8414194101324273239434853567[CỔ ĐÔNG],K9,Table8414194101324273239434853567[LỢI NHUẬN GỘP]) -> 86936490 | N9: =SUMIF(Table8414194101324273239434853567[CỔ ĐÔNG],K9,Table8414194101324273239434853567[LỢI NHUẬN RÒNG]) -> 35594396 | O9: =SUMIF(Table8414194101324273239434853567[CỔ ĐÔNG],Table9515205111425283340444954578[[#This Row],[CỔ ĐÔNG]],Table8414194101324273239434853567[TỔNG NHẬN]) -> 3.8099541e+08
A10: S8 | B10: CHUNG | C10: 25 | D10: 5500000 | E10: 1227602 | F10: 174906.79 | G10: =D10+Table8414194101324273239434853567[[#This Row],[LỢI NHUẬN RÒNG]] -> 5674906.8 | K10: HUY | L10: =SUMIF(Table8414194101324273239434853567[CỔ ĐÔNG],K10,Table8414194101324273239434853567[VỐN CP]) -> 35435000 | M10: =SUMIF(Table8414194101324273239434853567[CỔ ĐÔNG],K10,Table8414194101324273239434853567[LỢI NHUẬN GỘP]) -> 6631403.4 | N10: =SUMIF(Table8414194101324273239434853567[CỔ ĐÔNG],K10,Table8414194101324273239434853567[LỢI NHUẬN RÒNG]) -> 1547774.8 | O10: =SUMIF(Table8414194101324273239434853567[CỔ ĐÔNG],Table9515205111425283340444954578[[#This Row],[CỔ ĐÔNG]],Table8414194101324273239434853567[TỔNG NHẬN]) -> 36982775
A11: S9 | B11: CHUNG | C11: 20 | D11: 14780000 | E11: 4201309.2 | F11: 2689105.8 | G11: =D11+Table8414194101324273239434853567[[#This Row],[LỢI NHUẬN RÒNG]] -> 17469106 | K11: HUY ANH | L11: =SUMIF(Table8414194101324273239434853567[CỔ ĐÔNG],K11,Table8414194101324273239434853567[VỐN CP]) -> 96351667 | M11: =SUMIF(Table8414194101324273239434853567[CỔ ĐÔNG],K11,Table8414194101324273239434853567[LỢI NHUẬN GỘP]) -> 24411979 | N11: =SUMIF(Table8414194101324273239434853567[CỔ ĐÔNG],K11,Table8414194101324273239434853567[LỢI NHUẬN RÒNG]) -> 10375193 | O11: =SUMIF(Table8414194101324273239434853567[CỔ ĐÔNG],Table9515205111425283340444954578[[#This Row],[CỔ ĐÔNG]],Table8414194101324273239434853567[TỔNG NHẬN]) -> 1.0672686e+08
A12: S10 | B12: CHUNG | C12: 30 | D12: 13830000 | E12: 3093795.6 | F12: 771188.37 | G12: =D12+Table8414194101324273239434853567[[#This Row],[LỢI NHUẬN RÒNG]] -> 14601188 | K12: KIÊN | L12: =SUMIF(Table8414194101324273239434853567[CỔ ĐÔNG],K12,Table8414194101324273239434853567[VỐN CP]) -> 78370000 | M12: =SUMIF(Table8414194101324273239434853567[CỔ ĐÔNG],K12,Table8414194101324273239434853567[LỢI NHUẬN GỘP]) -> 19524251 | N12: =SUMIF(Table8414194101324273239434853567[CỔ ĐÔNG],K12,Table8414194101324273239434853567[LỢI NHUẬN RÒNG]) -> 8471387.6 | O12: =SUMIF(Table8414194101324273239434853567[CỔ ĐÔNG],Table9515205111425283340444954578[[#This Row],[CỔ ĐÔNG]],Table8414194101324273239434853567[TỔNG NHẬN]) -> 86841388
A13: S11 | B13: CHUNG | C13: 25 | K13: LUẬN | L13: =SUMIF(Table8414194101324273239434853567[CỔ ĐÔNG],K13,Table8414194101324273239434853567[VỐN CP]) -> 38973333 | M13: =SUMIF(Table8414194101324273239434853567[CỔ ĐÔNG],K13,Table8414194101324273239434853567[LỢI NHUẬN GỘP]) -> 11530686 | N13: =SUMIF(Table8414194101324273239434853567[CỔ ĐÔNG],K13,Table8414194101324273239434853567[LỢI NHUẬN RÒNG]) -> 5122350.8 | O13: =SUMIF(Table8414194101324273239434853567[CỔ ĐÔNG],Table9515205111425283340444954578[[#This Row],[CỔ ĐÔNG]],Table8414194101324273239434853567[TỔNG NHẬN]) -> 44095684
A14: S12 | B14: CHUNG | C14: 40 | D14: 20400000 | E14: 3285574.8 | F14: 636517.8 | G14: =D14+Table8414194101324273239434853567[[#This Row],[LỢI NHUẬN RÒNG]] -> 21036518 | K14: MẠNH | L14: =SUMIF(Table8414194101324273239434853567[CỔ ĐÔNG],K14,Table8414194101324273239434853567[VỐN CP]) -> 1.4526333e+08 | M14: =SUMIF(Table8414194101324273239434853567[CỔ ĐÔNG],K14,Table8414194101324273239434853567[LỢI NHUẬN GỘP]) -> 33778326 | N14: =SUMIF(Table8414194101324273239434853567[CỔ ĐÔNG],K14,Table8414194101324273239434853567[LỢI NHUẬN RÒNG]) -> 12196580 | O14: =SUMIF(Table8414194101324273239434853567[CỔ ĐÔNG],Table9515205111425283340444954578[[#This Row],[CỔ ĐÔNG]],Table8414194101324273239434853567[TỔNG NHẬN]) -> 1.575126e+08
A15: S13 | B15: CHUNG | C15: 15 | D15: 9150000 | E15: 1622441.1 | F15: 544765.41 | G15: =D15+Table8414194101324273239434853567[[#This Row],[LỢI NHUẬN RÒNG]] -> 9694765.4 | K15: NGỌC | L15: =SUMIF(Table8414194101324273239434853567[CỔ ĐÔNG],K15,Table8414194101324273239434853567[VỐN CP]) -> 62258333 | M15: =SUMIF(Table8414194101324273239434853567[CỔ ĐÔNG],K15,Table8414194101324273239434853567[LỢI NHUẬN GỘP]) -> 16888311 | N15: =SUMIF(Table8414194101324273239434853567[CỔ ĐÔNG],K15,Table8414194101324273239434853567[LỢI NHUẬN RÒNG]) -> 8112495.3 | O15: =SUMIF(Table8414194101324273239434853567[CỔ ĐÔNG],Table9515205111425283340444954578[[#This Row],[CỔ ĐÔNG]],Table8414194101324273239434853567[TỔNG NHẬN]) -> 70370829
A16: S14 | B16: CHUNG | C16: 20 | D16: 6160000 | E16: 2607176.8 | F16: 1756929.1 | G16: =D16+Table8414194101324273239434853567[[#This Row],[LỢI NHUẬN RÒNG]] -> 7916929.1 | K16: NỤ | L16: =SUMIF(Table8414194101324273239434853567[CỔ ĐÔNG],K16,Table8414194101324273239434853567[VỐN CP]) -> 52721667 | M16: =SUMIF(Table8414194101324273239434853567[CỔ ĐÔNG],K16,Table8414194101324273239434853567[LỢI NHUẬN GỘP]) -> 13695474 | N16: =SUMIF(Table8414194101324273239434853567[CỔ ĐÔNG],K16,Table8414194101324273239434853567[LỢI NHUẬN RÒNG]) -> 5973345.5 | O16: =SUMIF(Table8414194101324273239434853567[CỔ ĐÔNG],Table9515205111425283340444954578[[#This Row],[CỔ ĐÔNG]],Table8414194101324273239434853567[TỔNG NHẬN]) -> 58695012
A17: S15 | B17: CHUNG | C17: 20 | D17: 9000000 | E17: 39795 | F17: -873457.87 | G17: =D17+Table8414194101324273239434853567[[#This Row],[LỢI NHUẬN RÒNG]] -> 8126542.1 | K17: TÙNG | L17: =SUMIF(Table8414194101324273239434853567[CỔ ĐÔNG],K17,Table8414194101324273239434853567[VỐN CP]) -> 162455000 | M17: =SUMIF(Table8414194101324273239434853567[CỔ ĐÔNG],K17,Table8414194101324273239434853567[LỢI NHUẬN GỘP]) -> 45970807 | N17: =SUMIF(Table8414194101324273239434853567[CỔ ĐÔNG],K17,Table8414194101324273239434853567[LỢI NHUẬN RÒNG]) -> 20718485 | O17: =SUMIF(Table8414194101324273239434853567[CỔ ĐÔNG],Table9515205111425283340444954578[[#This Row],[CỔ ĐÔNG]],Table8414194101324273239434853567[TỔNG NHẬN]) -> 1.8322617e+08
A18: S16 | B18: CHUNG | C18: 20 | D18: 5000000 | E18: 2738351.3 | F18: 2068943.2 | G18: =D18+Table8414194101324273239434853567[[#This Row],[LỢI NHUẬN RÒNG]] -> 7068943.2 | K18: CƯỜNG | L18: =SUMIF(Table8414194101324273239434853567[CỔ ĐÔNG],K18,Table8414194101324273239434853567[VỐN CP]) -> 1583333.3 | M18: =SUMIF(Table8414194101324273239434853567[CỔ ĐÔNG],K18,Table8414194101324273239434853567[LỢI NHUẬN GỘP]) -> 600199.47 | N18: =SUMIF(Table8414194101324273239434853567[CỔ ĐÔNG],K18,Table8414194101324273239434853567[LỢI NHUẬN RÒNG]) -> 386246.55 | O18: =SUMIF(Table8414194101324273239434853567[CỔ ĐÔNG],Table9515205111425283340444954578[[#This Row],[CỔ ĐÔNG]],Table8414194101324273239434853567[TỔNG NHẬN]) -> 1969579.9
A19: S17 | B19: CHUNG | C19: 10 | D19: 1100000 | E19: 1123431 | F19: 751442.91 | G19: =D19+Table8414194101324273239434853567[[#This Row],[LỢI NHUẬN RÒNG]] -> 1851442.9 | K19: HƯƠNG ANH | L19: =SUMIF(Table8414194101324273239434853567[CỔ ĐÔNG],K19,Table8414194101324273239434853567[VỐN CP]) -> 2533333.3 | M19: =SUMIF(Table8414194101324273239434853567[CỔ ĐÔNG],K19,Table8414194101324273239434853567[LỢI NHUẬN GỘP]) -> 994823.32 | N19: =SUMIF(Table8414194101324273239434853567[CỔ ĐÔNG],K19,Table8414194101324273239434853567[LỢI NHUẬN RÒNG]) -> 593994.89 | O19: =SUMIF(Table8414194101324273239434853567[CỔ ĐÔNG],Table9515205111425283340444954578[[#This Row],[CỔ ĐÔNG]],Table8414194101324273239434853567[TỔNG NHẬN]) -> 3127328.2
A20: S1 | B20: Đ.THẮNG | C20: 10 | D20: 2400000 | E20: 771393.4 | F20: 428227.1 | G20: =D20+Table8414194101324273239434853567[[#This Row],[LỢI NHUẬN RÒNG]] -> 2828227.1 | K20: HOÀNG ANH | L20: =SUMIF(Table8414194101324273239434853567[CỔ ĐÔNG],K20,Table8414194101324273239434853567[VỐN CP]) -> 2083333.3 | M20: =SUMIF(Table8414194101324273239434853567[CỔ ĐÔNG],K20,Table8414194101324273239434853567[LỢI NHUẬN GỘP]) -> 795517.27 | N20: =SUMIF(Table8414194101324273239434853567[CỔ ĐÔNG],K20,Table8414194101324273239434853567[LỢI NHUẬN RÒNG]) -> 456663.99 | O20: =SUMIF(Table8414194101324273239434853567[CỔ ĐÔNG],Table9515205111425283340444954578[[#This Row],[CỔ ĐÔNG]],Table8414194101324273239434853567[TỔNG NHẬN]) -> 2539997.3
A21: S2 | B21: Đ.THẮNG | C21: 10 | D21: 4933333.3 | E21: 503605.57 | F21: -172975.44 | G21: =D21+Table8414194101324273239434853567[[#This Row],[LỢI NHUẬN RÒNG]] -> 4760357.9 | K21: LÂM | L21: =SUMIF(Table8414194101324273239434853567[CỔ ĐÔNG],K21,Table8414194101324273239434853567[VỐN CP]) -> 89468333 | M21: =SUMIF(Table8414194101324273239434853567[CỔ ĐÔNG],K21,Table8414194101324273239434853567[LỢI NHUẬN GỘP]) -> 21052435 | N21: =SUMIF(Table8414194101324273239434853567[CỔ ĐÔNG],K21,Table8414194101324273239434853567[LỢI NHUẬN RÒNG]) -> 8619294.9 | O21: =SUMIF(Table8414194101324273239434853567[CỔ ĐÔNG],Table9515205111425283340444954578[[#This Row],[CỔ ĐÔNG]],Table8414194101324273239434853567[TỔNG NHẬN]) -> 98087628
